Workbook

Sheet Dashboard
B2: PAINEL FINANCEIRO EXECUTIVO — SETEMBRO DE 2026
B3: Moura Barretto Engenharia Ltda (PJ) & Mateus Moura Barretto (PF)
B5: FATURAMENTO LÍQUIDO OPERACIONAL | E5: DESPESAS OPERACIONAIS PJ | H5: LUCRO LÍQUIDO PJ GERADO | K5: CUSTO DE VIDA PF (REALIZADO)
B6: =SUM(Lancamentos!J2:J4) | E6: =SUMIFS(Lancamentos!J:J, Lancamentos!E:E, "PJ", Lancamentos!F:F, "Despesa") | H6: =B6-E6 | K6: =SUMIFS(Lancamentos!J:J, Lancamentos!E:E, "PF", Lancamentos!F:F, "Despesa")
B8: RESUMO E CONCILIAÇÃO FINANCEIRA MÊS A MÊS
B9: Indicador / Conceito | C9: PJ (Escritório) | D9: PF (Pessoal) | E9: Consolidado Geral | F9: Observações Estratégicas
B10: Receita Bruta / Entradas de Projetos | C10: =Lancamentos!J2+Lancamentos!J3 | D10: =Lancamentos!J4 | E10: =C10+D10 | F10: Grado (R$ 7.200) + Wise Portugal 1575 € (~R$ 9.360)
B11: (-) Custos Operacionais da Empresa | C11: =E6 | D11: 0 | E11: =C11+D11 | F11: Equipe, Coworking, Softwares, Tributos, Viagens trabalho
B12: (=) Lucro Líquido Operacional PJ | C12: =C10-C11 | D12: — | E12: =C12 | F12: Capacidade real da empresa remunerar o sócio
B13: (-) Despesas Pessoais Pagas pela PJ | C13: =Conciliacao_PF_PJ!C7 | D13: — | E13: =C13 | F13: Carro RCI, Ocean Breeze, CEMIG, Lutas pagos no CNPJ
B14: (-) Pró-labore Direto Transferido (Pix) | C14: =Conciliacao_PF_PJ!C8 | D14: — | E14: =C14 | F14: Retiradas financeiras em conta
B15: (=) Total Transferido da PJ para PF | C15: =C13+C14 | D15: — | E15: =C15 | F15: Remuneração Total Realizada do Sócio no mês
B16: Total de Gastos de Vida PF no Mês | C16: — | D16: =K6 | E16: =D16 | F16: Moradia, Alimentação, Benjamim, Saúde, Carro, Lazer
B17: Alívio Imediato: Parcelas Encerradas em Setembro | C17: — | D17: 1425.89 | E17: 1425.89 | F17: Casas Bahia (R$ 678), Promo (R$ 633), Moda Infantil (R$ 113)
B18: Projeção de Fatura PF Pós-Alívio (Outubro) | C18: — | D18: =D16-D17 | E18: =D18 | F18: Custo projetado com término dessas 3 parcelas antigas
B21: COMPARATIVO: META / ORÇAMENTO BASE vs. REALIZADO (SETEMBRO/2026)
B22: Macro-Categoria | C22: Tipo | D22: Orçamento Base (Meta) | E22: Realizado Setembro | F22: Diferença (R$) | G22: Status / Diagnóstico
B23: Moradia & Habitação | C23: PF | D23: 6973.33 | E23: =SUMIFS(Lancamentos!J:J, Lancamentos!G:G, "Moradia") | F23: =D23-E23 | G23: Dentro do limite (Casa SSA/Ocean Breeze e aluguel)
B24: Alimentação (Mercados + Restaurantes) | C24: PF | D24: 5000 | E24: =SUMIFS(Lancamentos!J:J, Lancamentos!G:G, "Alimentação") | F24: =D24-E24 | G24: Supermercados (Mart Minas/Buritis) + Lazer
B25: Saúde & Bem-Estar | C25: PF | D25: 2510 | E25: =SUMIFS(Lancamentos!J:J, Lancamentos!G:G, "Saúde & Bem-Estar") | F25: =D25-E25 | G25: Unimed (R$ 1.546) + Farmácias + Lutas/Jiu-jitsu
B26: Educação (Benjamim) | C26: PF | D26: 2437.29 | E26: =SUMIFS(Lancamentos!J:J, Lancamentos!G:G, "Educação (Benjamim)") | F26: =D26-E26 | G26: Escola (R$ 1.870) + Inglês (R$ 240) + Vestuário
B27: Transporte & Veículo | C27: PF | D27: 4000 | E27: =SUMIFS(Lancamentos!J:J, Lancamentos!G:G, "Transporte & Veículos") | F27: =D27-E27 | G27: Carro Nissan RCI + Combustíveis nos postos
B28: Compras Pessoais, Lazer & Parcelas | C28: PF | D28: 3750 | E28: =SUMIFS(Lancamentos!J:J, Lancamentos!G:G, "Compras & Lazer") | F28: =D28-E28 | G28: Parcelas antigas que já terminaram
B29: Custos Operacionais Escritório | C29: PJ | D29: 5689 | E29: =E6 | F29: =D29-E29 | G29: Abaixo do orçado! (Meta R$ 5.689 vs Real R$ 4.674)
B30: TOTAL GERAL | C30: PF+PJ | D30: =SUM(D23:D29) | E30: =SUM(E23:E29) | F30: =D30-E30 | G30: Controle orçamentário consolidado

Sheet Dashboard_Grupos
B2: DASHBOARD ANALÍTICO POR GRUPOS & SUBGRUPOS (SETEMBRO/2026)
B3: Visão estruturada por tópicos para gestão de gastos da Pessoa Física e Pessoa Jurídica
B5: 👤 GRUPO PESSOAL (PESSOA FÍSICA - PF)
B6: Tópico / Grupo | C6: Subgrupo / Detalhamento | D6: Realizado Set/26 | E6: % Total PF | F6: Meta Proposta | G6: Diferença | H6: Diagnóstico & Estratégia de Redução
B7: 1. ALIMENTAÇÃO | C7: Supermercados (Mart Minas + Buritis) | D7: =SUMIFS(Lancamentos!J:J, Lancamentos!E:E, "PF", Lancamentos!H:H, "Supermercados") | E7: =D7/$D$35 | F7: 2200 | G7: =F7-D7 | H7: Compra grande planejada + compras de reposição
B8: 1. ALIMENTAÇÃO | C8: Restaurantes, Saídas & Fins de Semana | D8: =SUMIFS(Lancamentos!J:J, Lancamentos!E:E, "PF", Lancamentos!H:H, "Restaurantes & Lanches") | E8: =D8/$D$35 | F8: 900 | G8: =F8-D8 | H8: Cota de R$ 225 por fim de semana para sair com família
B9: 1. ALIMENTAÇÃO | C9: Feira Livre, Padarias, Pastelzinho & Granel | D9: =SUMIFS(Lancamentos!J:J, Lancamentos!E:E, "PF", Lancamentos!H:H, "Feira / Padaria")+SUMIFS(Lancamentos!J:J, Lancamentos!E:E, "PF", Lancamentos!H:H, "Padaria / Lanches")+SUMIFS(Lancamentos!J:J, Lancamentos!E:E, "PF", Lancamentos!H:H, "Hortifruti / Feira")+SUMIFS(Lancamentos!J:J, Lancamentos!E:E, "PF", Lancamentos!H:H, "Hortifruti / Granel") | E9: =D9/$D$35 | F9: 400 | G9: =F9-D9 | H9: 1 feira semanal para frescos (~R$ 100/semana)
B10: 1. ALIMENTAÇÃO | C10: Subtotal Alimentação | D10: =SUM(D7:D9) | E10: =D10/$D$35 | F10: 3500 | G10: =F10-D10 | H10: Economia potencial de mais de R$ 2.200/mês
B11: 2. CARRO & TRANSPORTE | C11: Parcela Financiamento Carro (Banco RCI) | D11: =SUMIFS(Lancamentos!J:J, Lancamentos!E:E, "PF", Lancamentos!H:H, "Parcela Carro") | E11: =D11/$D$35 | F11: 2080.09 | G11: =F11-D11 | H11: Parcela fixa regular (Setembro teve 2 parcelas pagas)
B12: 2. CARRO & TRANSPORTE | C12: Combustível nos Postos (Mariano, Pedra Forte) | D12: =SUMIFS(Lancamentos!J:J, Lancamentos!E:E, "PF", Lancamentos!H:H, "Combustível") | E12: =D12/$D$35 | F12: 900 | G12: =F12-D12 | H12: Otimizar deslocamentos e lançar viagens PJ no CNPJ
B13: 2. CARRO & TRANSPORTE | C13: Passagens, Uber & Pedágios | D13: =SUMIFS(Lancamentos!J:J, Lancamentos!E:E, "PF", Lancamentos!H:H, "Passagens Aéreas")+SUMIFS(Lancamentos!J:J, Lancamentos!E:E, "PF", Lancamentos!H:H, "Passagens Terrestres")+SUMIFS(Lancamentos!J:J, Lancamentos!E:E, "PF", Lancamentos!H:H, "Mobilidade Urbana")+SUMIFS(Lancamentos!J:J, Lancamentos!E:E, "PF", Lancamentos!H:H, "Pedágio") | E13: =D13/$D$35 | F13: 0 | G13: =F13-D13 | H13: Latam (3/4) encerra em Outubro! Zero em Novembro
B14: 2. CARRO & TRANSPORTE | C14: Subtotal Carro & Transporte | D14: =SUM(D11:D13) | E14: =D14/$D$35 | F14: 2980.09 | G14: =F14-D14 | H14: Queda de R$ 4.160 para R$ 2.080 na parcela do carro
B15: 3. MORADIA & HABITAÇÃO | C15: Imóvel Salvador (Ocean Breeze / Costa Azul) | D15: =SUMIFS(Lancamentos!J:J, Lancamentos!E:E, "PF", Lancamentos!H:H, "Imóvel Salvador") | E15: =D15/$D$35 | F15: 1662.67 | G15: =F15-D15 | H15: Fase 2: Alugar/monetizar para zerar este custo
B16: 3. MORADIA & HABITAÇÃO | C16: Aluguel Residencial Pouso Alegre (Joelma) | D16: =SUMIFS(Lancamentos!J:J, Lancamentos!E:E, "PF", Lancamentos!H:H, "Aluguel Residencial") | E16: =D16/$D$35 | F16: 800 | G16: =F16-D16 | H16: Aluguel residencial fixo mensal
B17: 3. MORADIA & HABITAÇÃO | C17: Energia Elétrica (CEMIG Minas Gerais) | D17: =SUMIFS(Lancamentos!J:J, Lancamentos!E:E, "PF", Lancamentos!H:H, "Energia Elétrica") | E17: =D17/$D$35 | F17: 550 | G17: =F17-D17 | H17: Contas de luz da residência
B18: 3. MORADIA & HABITAÇÃO | C18: Telefonia Celular (TIM) | D18: =SUMIFS(Lancamentos!J:J, Lancamentos!E:E, "PF", Lancamentos!H:H, "Conectividade / Telefone") | E18: =D18/$D$35 | F18: 125 | G18: =F18-D18 | H18: Planos de celular pessoal
B19: 3. MORADIA & HABITAÇÃO | C19: Subtotal Moradia | D19: =SUM(D15:D18) | E19: =D19/$D$35 | F19: 3137.67 | G19: =F19-D19 | H19: Na Fase 2, alugando Salvador, desce para R$ 1.475
B20: 4. EDUCAÇÃO (BENJAMIM) | C20: Escola Benjamim (Associação das Obras) | D20: =SUMIFS(Lancamentos!J:J, Lancamentos!E:E, "PF", Lancamentos!H:H, "Escola") | E20: =D20/$D$35 | F20: 1870 | G20: =F20-D20 | H20: Mensalidade escolar regular
B21: 4. EDUCAÇÃO (BENJAMIM) | C21: Curso de Inglês (Spectrum Line) | D21: =SUMIFS(Lancamentos!J:J, Lancamentos!E:E, "PF", Lancamentos!H:H, "Cursos") | E21: =D21/$D$35 | F21: 240 | G21: =F21-D21 | H21: Inglês curricular
B22: 4. EDUCAÇÃO (BENJAMIM) | C22: Vestuário Infantil, Brinquedos & Material | D22: =SUMIFS(Lancamentos!J:J, Lancamentos!E:E, "PF", Lancamentos!H:H, "Vestuário Infantil")+SUMIFS(Lancamentos!J:J, Lancamentos!E:E, "PF", Lancamentos!H:H, "Lazer / Infantil")+SUMIFS(Lancamentos!J:J, Lancamentos!E:E, "PF", Lancamentos!H:H, "Material Escolar") | E22: =D22/$D$35 | F22: 100 | G22: =F22-D22 | H22: Sigga Moda Infantil quitada em Setembro (4/4)!
B23: 4. EDUCAÇÃO (BENJAMIM) | C23: Subtotal Educação (Benjamim) | D23: =SUM(D20:D22) | E23: =D23/$D$35 | F23: 2210 | G23: =F23-D23 | H23: Investimento prioritário preservado
B24: 5. SAÚDE & BEM-ESTAR | C24: Plano de Saúde Familiar (Unimed) | D24: =SUMIFS(Lancamentos!J:J, Lancamentos!E:E, "PF", Lancamentos!H:H, "Plano de Saúde") | E24: =D24/$D$35 | F24: 1546.83 | G24: =F24-D24 | H24: Proteção familiar essencial (3 boletos Unimed)
B25: 5. SAÚDE & BEM-ESTAR | C25: Atividades Físicas & Lutas (Respect / BL) | D25: =SUMIFS(Lancamentos!J:J, Lancamentos!E:E, "PF", Lancamentos!H:H, "Atividades Físicas") | E25: =D25/$D$35 | F25: 500 | G25: =F25-D25 | H25: Jiu-jitsu parcela 2/3 termina em Outubro
B26: 5. SAÚDE & BEM-ESTAR | C26: Farmácias & Odontologia (Medicamentos) | D26: =SUMIFS(Lancamentos!J:J, Lancamentos!E:E, "PF", Lancamentos!H:H, "Farmácia")+SUMIFS(Lancamentos!J:J, Lancamentos!E:E, "PF", Lancamentos!H:H, "Odontologia") | E26: =D26/$D$35 | F26: 300 | G26: =F26-D26 | H26: Farmácia de rotina e prevenção
B27: 5. SAÚDE & BEM-ESTAR | C27: Previdência Privada (BB Previdência) | D27: =SUMIFS(Lancamentos!J:J, Lancamentos!E:E, "PF", Lancamentos!H:H, "Previdência Privada") | E27: =D27/$D$35 | F27: 226 | G27: =F27-D27 | H27: Aporte para aposentadoria privada
B28: 5. SAÚDE & BEM-ESTAR | C28: Subtotal Saúde & Bem-Estar | D28: =SUM(D24:D27) | E28: =D28/$D$35 | F28: 2572.83 | G28: =F28-D28 | H28: Saúde estruturada
B29: 6. COMPRAS & PARCELAS | C29: Parcelamentos Antigos (Casas Bahia + Promo) | D29: =SUMIFS(Lancamentos!J:J, Lancamentos!E:E, "PF", Lancamentos!H:H, "Parcelamentos Antigos") | E29: =D29/$D$35 | F29: 111.63 | G29: =F29-D29 | H29: QUITADOS! Casas Bahia (10/10) e Promo (3/3) zeram
B30: 6. COMPRAS & PARCELAS | C30: Streaming & Assinaturas (Netflix, Spotify...) | D30: =SUMIFS(Lancamentos!J:J, Lancamentos!E:E, "PF", Lancamentos!H:H, "Streaming / Assinaturas") | E30: =D30/$D$35 | F30: 100 | G30: =F30-D30 | H30: Cancelar canais extras do Amazon Prime
B31: 6. COMPRAS & PARCELAS | C31: Pets & Agropecuária (Rações / Cuidados) | D31: =SUMIFS(Lancamentos!J:J, Lancamentos!E:E, "PF", Lancamentos!H:H, "Pets / Agropecuária") | E31: =D31/$D$35 | F31: 250 | G31: =F31-D31 | H31: Cachorro e galinhas
B32: 6. COMPRAS & PARCELAS | C32: Compras Online, Vestuário & Utilidades | D32: =SUMIFS(Lancamentos!J:J, Lancamentos!E:E, "PF", Lancamentos!H:H, "Compras Online")+SUMIFS(Lancamentos!J:J, Lancamentos!E:E, "PF", Lancamentos!H:H, "Vestuário / Calçados")+SUMIFS(Lancamentos!J:J, Lancamentos!E:E, "PF", Lancamentos!H:H, "Casa & Utilidades")+SUMIFS(Lancamentos!J:J, Lancamentos!E:E, "PF", Lancamentos!H:H, "Diversos")+SUMIFS(Lancamentos!J:J, Lancamentos!E:E, "PF", Lancamentos!H:H, "Vestuário / Casa")+SUMIFS(Lancamentos!J:J, Lancamentos!E:E, "PF", Lancamentos!H:H, "Tarifas Cartão")+SUMIFS(Lancamentos!J:J, Lancamentos!E:E, "PF", Lancamentos!H:H, "Farmácia / Cosméticos") | E32: =D32/$D$35 | F32: 300 | G32: =F32-D32 | H32: Compras pontuais à vista
B33: 6. COMPRAS & PARCELAS | C33: Subtotal Compras & Parcelas | D33: =SUM(D29:D32) | E33: =D33/$D$35 | F33: 761.63 | G33: =F33-D33 | H33: Alívio conquistado de R$ 1.425/mês
B34: TOTAL GERAL PESSOA FÍSICA (PF) | D34: =D10+D14+D19+D23+D28+D33 | E34: 1 | F34: =F10+F14+F19+F23+F28+F33 | G34: =F34-D34 | H34: Redução planejada de R$ 23.298 para R$ 15.162 na PF!
B37: 🏢 GRUPO EMPRESA / ESCRITÓRIO (PESSOA JURÍDICA - PJ)
B38: Tópico / Grupo | C38: Subgrupo / Detalhamento | D38: Realizado Set/26 | E38: % Total PF | F38: Meta Proposta | G38: Diferença | H38: Diagnóstico & Estratégia de Redução
B39: 1. EQUIPE & ESTÁGIO | C39: Estagiária Técnica (Fernanda Mayra) | D39: =SUMIFS(Lancamentos!J:J, Lancamentos!E:E, "PJ", Lancamentos!H:H, "Equipe & Estágio") | E39: =D39/$D$45 | F39: 1700 | G39: =F39-D39 | H39: Bolsa de estágio regular mantida
B40: 2. INFRAESTRUTURA | C40: Coworking & Internet Escritório | D40: =SUMIFS(Lancamentos!J:J, Lancamentos!E:E, "PJ", Lancamentos!H:H, "Infraestrutura / Coworking")+SUMIFS(Lancamentos!J:J, Lancamentos!E:E, "PJ", Lancamentos!H:H, "Conectividade / Internet") | E40: =D40/$D$45 | F40: 650 | G40: =F40-D40 | H40: DW Treinamento R$ 525 + BRT Internet R$ 99
B41: 3. VIAGENS A TRABALHO | C41: Passagens Aéreas GOL & Seguro Frota | D41: =SUMIFS(Lancamentos!J:J, Lancamentos!E:E, "PJ", Lancamentos!H:H, "Viagens & Deslocamento")+SUMIFS(Lancamentos!J:J, Lancamentos!E:E, "PJ", Lancamentos!H:H, "Operação & Frota") | E41: =D41/$D$45 | F41: 500 | G41: =F41-D41 | H41: Passagens GOL (2/2) encerrada! Parcela 2/3 encerra em Out
B42: 4. TRIBUTOS & TAXAS | C42: INSS / DCTFWeb, CREA PF & ABECE | D42: =SUMIFS(Lancamentos!J:J, Lancamentos!E:E, "PJ", Lancamentos!H:H, "Tributos & Taxas") | E42: =D42/$D$45 | F42: 800 | G42: =F42-D42 | H42: Obrigações tributárias e de classe do escritório
B43: 5. SOFTWARES & CURSOS | C43: Google Workspace & Pós-Graduação IPOG | D43: =SUMIFS(Lancamentos!J:J, Lancamentos!E:E, "PJ", Lancamentos!H:H, "Softwares & TI")+SUMIFS(Lancamentos!J:J, Lancamentos!E:E, "PJ", Lancamentos!H:H, "Capacitação & Cursos") | E43: =D43/$D$45 | F43: 500 | G43: =F43-D43 | H43: Assinatura Google R$ 98 + IPOG R$ 279
B44: 6. TARIFAS & OPERAÇÕES | C44: Tarifas Bancárias Caixa & Deslocamentos | D44: =SUMIFS(Lancamentos!J:J, Lancamentos!E:E, "PJ", Lancamentos!H:H, "Tarifas Bancárias")+SUMIFS(Lancamentos!J:J, Lancamentos!E:E, "PJ", Lancamentos!H:H, "Serviços Operacionais")+SUMIFS(Lancamentos!J:J, Lancamentos!E:E, "PJ", Lancamentos!H:H, "Alimentação Operacional")+SUMIFS(Lancamentos!J:J, Lancamentos!E:E, "PJ", Lancamentos!H:H, "Deslocamento Operacional") | E44: =D44/$D$45 | F44: 350 | G44: =F44-D44 | H44: Operação enxuta do dia a dia
...

Sheet Lancamentos
A1: ID | B1: Data | C1: Competência | D1: Conta / Meio | E1: Entidade | F1: Tipo | G1: Categoria | H1: Subcategoria | I1: Descrição / Estabelecimento | J1: Valor (R$) | K1: Conta Pagadora | L1: Cruzamento PF/PJ | M1: Status | N1: Observações Detalhadas
A2: 1 | B2: 2026-09-21 | C2: 09/2026 | D2: Conta Caixa PJ | E2: PJ | F2: Receita | G2: Receita Operacional | H2: Projetos Nacionais | I2: Grado Engenharia - Reforma Prédio Ondina (Rampa) | J2: 3500 | K2: Conta Caixa PJ | L2: Normal PJ | M2: Liquidado | N2: TED recebida
A3: 2 | B3: 2026-09-21 | C3: 09/2026 | D3: Conta Caixa PJ | E3: PJ | F3: Receita | G3: Receita Operacional | H3: Projetos Nacionais | I3: Grado Engenharia - Reforma Prédio Ondina (Mezanino) | J3: 3700 | K3: Conta Caixa PJ | L3: Normal PJ | M3: Liquidado | N3: TED recebida
A4: 3 | B4: 2026-09-04 | C4: 09/2026 | D4: Wise Portugal | E4: PJ | F4: Receita | G4: Receita Internacional | H4: Projetos Internacionais | I4: TDP Braga (Portugal) - 1.575,00 Euros | J4: 9360 | K4: Wise / PF | L4: Normal PJ | M4: Liquidado | N4: Contrato recorrente internacional
A5: 4 | B5: 2026-09-04 | C5: 09/2026 | D5: Conta Caixa PJ | E5: PJ | F5: Despesa | G5: Custos Escritório | H5: Equipe & Estágio | I5: Fernanda Mayra Campos Barretto (Estagiária) | J5: 1621 | K5: Conta Caixa PJ | L5: Normal PJ | M5: Liquidado | N5: Bolsa de estágio mensal
A6: 5 | B6: 2026-09-23 | C6: 09/2026 | D6: Conta Nubank PJ | E6: PJ | F6: Despesa | G6: Custos Escritório | H6: Equipe & Estágio | I6: Fernanda Mayra Campos Barretto | J6: 80 | K6: Conta Nubank PJ | L6: Normal PJ | M6: Liquidado | N6: Complemento estágio / reembolso
A7: 6 | B7: 2026-09-04 | C7: 09/2026 | D7: Conta Nubank PF | E7: PJ | F7: Despesa | G7: Custos Escritório | H7: Infraestrutura / Coworking | I7: D W Treinamento e Desenvolvimento Ltda (Coworking) | J7: 525 | K7: Conta Nubank PF | L7: PF pagou PJ | M7: Liquidado | N7: Aluguel escritório Pouso Alegre pago via PF
A8: 7 | B8: 2026-09-04 | C8: 09/2026 | D8: Conta Nubank PJ | E8: PJ | F8: Despesa | G8: Custos Escritório | H8: Conectividade / Internet | I8: BRT Telecomunicações / CVS Telecom (Internet) | J8: 99.9 | K8: Conta Nubank PJ | L8: Normal PJ | M8: Liquidado | N8: Internet Pouso Alegre
A9: 8 | B9: 2026-09-02 | C9: 09/2026 | D9: Cartão Nubank PJ | E9: PJ | F9: Despesa | G9: Custos Escritório | H9: Softwares & TI | I9: Google Workspace (GSuite / Drive / E-mail) | J9: 98 | K9: Cartão Nubank PJ | L9: Normal PJ | M9: Liquidado | N9: Assinatura mensal Google
A10: 9 | B10: 2026-09-04 | C10: 09/2026 | D10: Conta Nubank PF | E10: PJ | F10: Despesa | G10: Custos Escritório | H10: Tributos & Taxas | I10: Receita Federal - INSS / DCTFWeb Moura Barretto | J10: 220 | K10: Conta Nubank PF | L10: PF pagou PJ | M10: Liquidado | N10: Tributo da empresa pago com conta pessoal
A11: 10 | B11: 2026-09-04 | C11: 09/2026 | D11: Conta Nubank PF | E11: PJ | F11: Despesa | G11: Custos Escritório | H11: Tributos & Taxas | I11: CREA PF (Conselho Regional de Engenharia) | J11: 228.84 | K11: Conta Nubank PF | L11: PF pagou PJ | M11: Liquidado | N11: Anuidade profissional engenharia
A12: 11 | B12: 2026-08-28 | C12: 09/2026 | D12: Conta Nubank PF | E12: PJ | F12: Despesa | G12: Custos Escritório | H12: Tributos & Taxas | I12: ABECE - Associação Bras. Engenharia Estrutural | J12: 110 | K12: Conta Nubank PF | L12: PF pagou PJ | M12: Liquidado | N12: Associação de classe técnica
A13: 12 | B13: 2026-09-04 | C13: 09/2026 | D13: Conta Caixa PJ | E13: PJ | F13: Despesa | G13: Custos Escritório | H13: Capacitação & Cursos | I13: IPOG (Pós-graduação / Especialização Técnica) | J13: 279.14 | K13: Conta Caixa PJ | L13: Normal PJ | M13: Liquidado | N13: Curso técnico engenharia
... A181: 180 | B181: 2026-09-29 | C181: 09/2026 | D181: Cartão Nubank PF | E181: PF | F181: Despesa | G181: Alimentação | H181: Padaria / Lanches | I181: Mp *Rosinairibeir | J181: 25 | K181: Cartão Nubank PF | L181: Normal PF | M181: Liquidado | N181: Padaria

Sheet Conciliacao_PF_PJ
B2: CONCILIAÇÃO FINANCEIRA ENTRE EMPRESA (PJ) E SÓCIO (PF)
B3: Demonstrativo exato de quem pagou o quê e apuração da remuneração real do sócio
B5: 1. RESUMO DOS REPASSES E GASTOS CRUZADOS (SETEMBRO/2026)
B6: Conceito | C6: Valor (R$) | D6: Impacto Contábil / Financeiro
B7: Despesas Pessoais Pagas Diretamente pela Empresa (Caixa PJ + Nubank PJ) | C7: =SUMIFS(Lancamentos!J:J, Lancamentos!L:L, "PJ bancou PF") | D7: Pró-Labore / Distribuição Indireta de Lucros
B8: Pró-Labore Direto Transferido da PJ para PF (Pix na conta) | C8: 200 | D8: Retirada financeira direta do sócio
B9: TOTAL BANCADO PELA EMPRESA PARA A VIDA PESSOAL | C9: =C7+C8 | D9: Remuneração Total Realizada do Sócio
B10: Despesas da Empresa Pagas com Recursos do Sócio (Nubank PF) | C10: =SUMIFS(Lancamentos!J:J, Lancamentos!L:L, "PF pagou PJ") | D10: Aporte do sócio / Reembolso devido pela PJ
B11: SALDO LÍQUIDO RETIRADO PELO SÓCIO (PJ -> PF) | C11: =C9-C10 | D11: Transferência líquida real de riqueza da PJ para PF
B14: 2. DETALHAMENTO: CONTAS PESSOAIS (PF) QUE SAÍRAM DA EMPRESA (PJ)
B15: Data | C15: Conta Saída | D15: Categoria | E15: Descrição | F15: Valor (R$) | G15: Motivo / Destino
B16: 01/09/2026 | C16: Conta Caixa PJ | D16: Transporte & Veículo | E16: Banco RCI Brasil (Parcela Financiamento Carro) | F16: 2080.09 | G16: Veículo pessoal
B17: 28/09/2026 | C17: Conta Caixa PJ | D17: Transporte & Veículo | E17: Banco RCI Brasil (Parcela Financiamento Carro 2) | F17: 2080.09 | G17: Veículo pessoal (regularização/adiantamento)
B18: 04/09/2026 | C18: Conta Caixa PJ | D18: Moradia | E18: Costa Azul Salvador / Ocean Breeze | F18: 1662.67 | G18: Condomínio/Parcela imóvel Salvador
B19: 18/09/2026 | C19: Conta Nubank PJ | D19: Moradia | E19: Joelma Pereira de Aquino Souza | F19: 800 | G19: Aluguel residencial
B20: 30/09/2026 | C20: Conta Caixa PJ | D20: Moradia | E20: CEMIG Distribuição MG (Conta 1) | F20: 382.8 | G20: Energia elétrica Pouso Alegre
B21: 30/09/2026 | C21: Conta Caixa PJ | D21: Moradia | E21: CEMIG Distribuição MG (Conta 2) | F21: 174.21 | G21: Energia elétrica
B22: 18/09/2026 | C22: Conta Nubank PJ | D22: Saúde & Exercício | E22: Escola Respect 4 Jiu-Jitsu | F22: 500 | G22: Atividade física
B23: 30/09/2026 | C23: Conta Caixa PJ | D23: Saúde & Exercício | E23: Escola de Lutas BL | F23: 169.9 | G23: Atividade física
B24: 03/09/2026 | C24: Conta Caixa PJ | D24: Transporte | E24: Mega Posto (Débito) | F24: 100 | G24: Combustível
B25: 03/09/2026 | C25: Conta Caixa PJ | D25: Transporte | E25: Posto Conceição (Débito) | F25: 100 | G25: Combustível
B26: 03/09/2026 | C26: Conta Caixa PJ | D26: Transporte | E26: Concessionária Bahia Norte | F26: 7.7 | G26: Pedágio
B27: 26/09/2026 | C27: Conta Caixa PJ | D27: Alimentação | E27: Supermercado Buritis | F27: 73.31 | G27: Mercado da família
... B29: 26/09/2026 | C29: Conta Caixa PJ | D29: Alimentação | E29: Nayara Pereira do | F29: 18 | G29: Serviço/Alimentação pessoal
B30: SUBTOTAL CONTAS PF PAGAS PELA PJ | F30: =SUM(F16:F29)

Sheet Previsao_Futura
B2: CRONOGRAMA DE PARCELAMENTOS & ALÍVIO FINANCEIRO FUTURO
B3: Mapeamento das parcelas em aberto e projeção da redução das faturas até o fim do ano
B5: 1. PARCELAS MAPEADAS NOS CARTÕES DE CRÉDITO
B6: Origem / Cartão | C6: Entidade | D6: Descrição da Compra | E6: Parcela Set/26 | F6: Valor Parcela | G6: Status Setembro | H6: Outubro/26 | I6: Novembro/26 | J6: Dezembro/26 | K6: Impacto no Fluxo de Caixa
B7: Cartão Nubank PF | C7: PF | D7: Grupo Casas Bahia | E7: 10/10 | F7: 678.77 | G7: ENCERRADA! | H7: 0 | I7: 0 | J7: 0 | K7: Economia imediata de R$ 678,77/mês
B8: Cartão Nubank PF | C8: PF | D8: Vai de Promo (Viagem) | E8: 3/3 | F8: 633.97 | G8: ENCERRADA! | H8: 0 | I8: 0 | J8: 0 | K8: Economia imediata de R$ 633,97/mês
B9: Cartão Nubank PF | C9: PF | D9: Sigga Moda Infantil | E9: 4/4 | F9: 113.15 | G9: ENCERRADA! | H9: 0 | I9: 0 | J9: 0 | K9: Economia imediata de R$ 113,15/mês
B10: Cartão Nubank PF | C10: PF | D10: Latam Linhas Aéreas | E10: 3/4 | F10: 426.53 | G10: Ativa | H10: 426.53 | I10: 0 | J10: 0 | K10: Encerra em Outubro! Zero em Novembro
B11: Cartão Nubank PF | C11: PF | D11: Respect 4 Jiu-Jitsu | E11: 2/3 | F11: 165 | G11: Ativa | H11: 165 | I11: 0 | J11: 0 | K11: Encerra em Outubro! Zero em Novembro
B12: Cartão Nubank PF | C12: PF | D12: Pg *Pza Comercio | E12: 3/6 | F12: 111.63 | G12: Ativa | H12: 111.63 | I12: 111.63 | J12: 111.63 | K12: Segue até Dezembro
B13: Cartão Nubank PJ | C13: PJ | D13: Gol Linhas Aéreas | E13: 2/2 | F13: 462.95 | G13: ENCERRADA! | H13: 0 | I13: 0 | J13: 0 | K13: Economia imediata de R$ 462,95/mês na PJ
B14: Cartão Nubank PJ | C14: PJ | D14: Gol Linhas Aéreas | E14: 2/3 | F14: 246.57 | G14: Ativa | H14: 246.57 | I14: 0 | J14: 0 | K14: Encerra em Outubro! Zero em Novembro
B15: Cartão Nubank PJ | C15: PJ | D15: Azul Seguros | E15: 9/10 | F15: 238.77 | G15: Ativa | H15: 238.77 | I15: 0 | J15: 0 | K15: Encerra em Outubro! Zero em Novembro
B16: TOTAL DAS PARCELAS NO MÊS | F16: =SUM(F7:F15) | H16: =SUM(H7:H15) | I16: =SUM(I7:I15) | J16: =SUM(J7:J15)
B18: ALÍVIO FINANCEIRO MENSAL CONQUISTADO (REDUÇÃO EM RELAÇÃO A SETEMBRO): | H18: =F16-H16 | I18: =F16-I16 | J18: =F16-J16

Sheet Plano_de_Contas
B2: ESTRUTURA DE CATEGORIAS & PLANO DE CONTAS PADRONIZADO
B3: Estrutura para categorizar extratos e faturas dos próximos meses com consistência
B5: Entidade | C5: Tipo | D5: Categoria Principal | E5: Subcategoria | F5: Descrição / Exemplos de Aplicação | G5: Conta Recomendada
B6: PJ | C6: Receita | D6: Receita Operacional | E6: Projetos Nacionais | F6: Honorários de projetos e laudos emitidos (Grado, Gráfico, etc.) | G6: Conta Caixa PJ / Nubank PJ
B7: PJ | C7: Receita | D7: Receita Internacional | E7: Projetos Internacionais | F7: Contrato internacional recorrente TDP Braga (Portugal) | G7: Wise -> Nubank/Caixa
B8: PJ | C8: Despesa | D8: Custos Escritório | E8: Equipe & Estágio | F8: Bolsa de estágio estagiários técnicos (Fernanda) | G8: Conta Caixa PJ
B9: PJ | C9: Despesa | D9: Custos Escritório | E9: Infraestrutura / Coworking | F9: Aluguel de sala, estação de trabalho (DW Treinamento) | G9: Conta Nubank PJ
B10: PJ | C10: Despesa | D10: Custos Escritório | E10: Conectividade / Internet | F10: Link de internet do escritório (BRT / CVS) | G10: Conta Nubank PJ
B11: PJ | C11: Despesa | D11: Custos Escritório | E11: Softwares & TI | F11: Google Workspace, licenças de cálculo/desenho (TQS/Eberick) | G11: Cartão Nubank PJ
B12: PJ | C12: Despesa | D12: Custos Escritório | E12: Tributos & Taxas | F12: Simples Nacional, ISS, INSS/DCTFWeb, CREA PJ, ABECE | G12: Conta Caixa PJ / Nubank PJ
B13: PJ | C13: Despesa | D13: Custos Escritório | E13: Capacitação & Cursos | F13: Especializações, cursos e pós-graduação (IPOG) | G13: Conta Caixa PJ
B14: PJ | C14: Despesa | D14: Custos Escritório | E14: Tarifas Bancárias | F14: Manutenção de conta, tarifas de Pix PJ e emissão de boletos | G14: Conta Caixa PJ
B15: PJ | C15: Despesa | D15: Custos Escritório | E15: Viagens & Deslocamento | F15: Passagens de avião para visitas técnicas e reuniões (Gol/Azul) | G15: Cartão Nubank PJ
B16: PF | C16: Despesa | D16: Moradia | E16: Imóvel Salvador | F16: Parcela / condomínio empreendimento Ocean Breeze Salvador | G16: Conta Nubank PF
... B36: PF | C36: Despesa | D36: Compras & Lazer | E36: Pets / Agropecuária | F36: Alimentação e cuidados cachorro/animais (Petagro, Sta Edwiges) | G36: Cartão Nubank PF
